Workbook

Sheet admissions
A1: Admission ID | B1: Parent Name | C1: Mobile | D1: Email | E1: Address | F1: City | G1: Student Name | H1: Age | I1: Gender | J1: School | K1: Grade | L1: Level | M1: Batch Code | N1: Mode | O1: Start Date | P1: End Date | Q1: Status | R1: Total Fee | S1: Discount | T1: Manual Adjustment | U1: Adjusted Fee | V1: Total Paid | W1: Pending | X1: Payment Status | Y1: Admission Source | Z1: Referral Type | AA1: Referrer Name | AB1: Created Date | AC1: Send Certificate | AD1: Certificate Status | AE1: Certificate Number | AF1: Certificate Issue Date | AG1: Certificate Sent Date | AH1: Certificate PDF URL | AI1: Certificate Image URL | AJ1: Certificate WhatsApp Status | AK1: Certificate WhatsApp Link | AL1: Certificate WhatsApp Sent Date | AM1: Certificate Error | AN1: Send Receipt | AO1: Receipt Status | AP1: Notification Status
A2: A1001 | B2: Divya Bisen | C2: 7898596308 | D2: bisendivya13@gmail.com | E2: 9a atlas Cosmos spring thane | F2: Thane | G2: Nitivya Katre | H2: 4 | I2: Male | J2: Millenium star kids | K2: Jr kg | L2: Basic | N2: Online | O2: 46091 | P2: 46142 | Q2: Active | R2: 4500 | S2: 0 | T2: 0 | U2: {=IF(R2:R1080="", "", R2:R1080 - IF(S2:S1080="", 0, S2:S1080) + IF(T2:T1080="", 0, T2:T1080))} | V2: =IF(A2="","",SUMIF(payments!B:B,A2,payments!D:D)) | W2: {=IF(U2:U1080="","",U2:U1080-V2:V1080)} | X2: {=IF(U2:U1080="","",IF(V2:V1080=0,"Not Started",IF(V2:V1080<U2:U1080,"Partial","Completed")))} | Y2: Friend Referral | Z2: Friend Referral | AA2: Https://excelkidshub.in/ | AB2: 46096.755
A3: A1002 | B3: Kirti Alkesh Tripathi | C3: 9112307291 | D3: kirti.tripathi0710@gmail.com | E3: Blue villa banglo,lane no 3,Vrindavan colony, kalwad road, opp bird blooming school near goodwill Fabian dhanori | F3: Pune | G3: Vedika Alkesh Tripathi | H3: 4 | I3: Female | J3: Symbiosis international school | K3: Ey-2 | L3: Advanced | N3: Offline | O3: 46091 | P3: 46157 | Q3: Active | R3: 8500 | S3: 0 | T3: 0 | U3: 8500 | V3: =IF(A3="","",SUMIF(payments!B:B,A3,payments!D:D)) | W3: 8500 | X3: Not Started | AA3: Https://excelkidshub.in/ | AB3: 46097.004
A4: A1003 | B4: Rishikesh Kakde | C4: 9359896551 | D4: shrutikakakde29@gmail.com | E4: Flat no.703,B wing, Nivasa uddan society, porwal road,lohegaon pune | F4: Pune | G4: Ridhanya Kakde | H4: 7 | I4: Female | J4: Dr.mar thephillous | K4: 2 | L4: Advanced | N4: Online | O4: 46091 | P4: 46167 | Q4: Active | R4: 0 | S4: 0 | T4: 0 | U4: 0 | V4: =IF(A4="","",SUMIF(payments!B:B,A4,payments!D:D)) | W4: 0 | X4: Not Started | Y4: Social Media | AA4: Https://excelkidshub.in/ | AB4: 46097.405
A5: A1004 | B5: Ranjeeta Limje | C5: 9636169689 | D5: nidhishlimje@gmail.com | E5: EBRO f 304 omaxe riviera Rudarpur | F5: Pune | G5: Yashvi Limje | H5: 5 | I5: Female | J5: Shiny star modern school rudrapur | K5: LKG | L5: Basic | N5: Online | O5: 46091 | P5: 46142 | Q5: Active | R5: 4500 | S5: 0 | T5: 0 | U5: 4500 | V5: =IF(A5="","",SUMIF(payments!B:B,A5,payments!D:D)) | W5: 4500 | X5: Not Started | Y5: Friend Referral | Z5: Friend Referral | AA5: Https://excelkidshub.in/ | AB5: 46098.508
A6: A1005 | B6: Shashikant Pandurang Suryawanshi | C6: 9763401609 | D6: shashi.surya@gmail.com | E6: A1302 Ganga new town, porwal road dhanori pune | F6: Pune | G6: Tanush Shashikant Suryawanshi | H6: 12 | I6: Male | J6: Dr. Martheophilus school | K6: 7 | L6: Advanced | N6: Offline | O6: 46091 | P6: 46157 | Q6: Active | R6: 4500 | S6: 0 | T6: 0 | U6: 4500 | V6: 4500 | W6: 0 | X6: Completed | Y6: Online | AA6: Https://excelkidshub.in/ | AB6: 46102.807
A7: A1006 | B7: Nishant Indapure | C7: 8421111038 | D7: indapureshweta@gmail.com | E7: Nirvana lifecity C Wing Flat no 308 Lohagon | F7: Pune | G7: Nehesh Nishant Indapure | H7: 13 | I7: Male | J7: Pune Internatinal school | K7: 7 | L7: Advanced | N7: Offline | O7: 46091 | P7: 46157 | Q7: Active | R7: 4500 | S7: 0 | T7: 1000 | U7: 5500 | V7: =IF(A7="","",SUMIF(payments!B:B,A7,payments!D:D)) | W7: 5500 | X7: Not Started | Y7: Friend Referral | Z7: Friend Referral | AA7: Https://excelkidshub.in/ | AB7: 46102.984
A8: A1007 | B8: Nishant Indapure | C8: 8421111038 | D8: indapureshweta@gmail.com | E8: Nirvana lifecity Lohagon Pune | F8: Pune | G8: Nehesh Indapure | H8: 13 | I8: Male | J8: Pune Internationl School | K8: 7 | L8: Advanced | M8: Offline L2-B10 Apr'26 | N8: Offline | O8: 46091 | P8: 46157 | Q8: Active | R8: 6500 | S8: 0 | T8: 0 | U8: 6500 | V8: 500 | W8: 6000 | X8: Partial | Y8: Friend Referral | Z8: Friend Referral | AA8: Https://excelkidshub.in/ | AB8: 46103.402
A9: A1008 | B9: Aayesha Jawed Shaikh | C9: 8888810799 | D9: aayesha.shaikh84@gmail.com | E9: Nirman Society,lane 11B, Mumjaba vasti, Dhanori | F9: Pune | G9: Aakib Jawed Shaikh | H9: 8 | I9: Male | J9: Dr. Mar Theophilus School | K9: 3 | L9: Advanced | M9: Offline L3-B9 Apr'26 | N9: Offline | O9: 46091 | P9: 46157 | Q9: Active | R9: 6500 | S9: 0 | T9: 0 | U9: 6500 | V9: 500 | W9: 6000 | X9: Partial | Y9: Friend Referral | Z9: Friend Referral | AA9: Https://excelkidshub.in/ | AB9: 46105.593
A10: A1009 | B10: Kartikkumar Shah | C10: 9998761858 | D10: honeykartikshah1@gmail.com | E10: Bungalow No 72, Lane no 7, Munjabwasti,Dhanori | F10: Pune | G10: Aayanshi Kartikkumar Shah | H10: 5 | I10: Female | J10: Dr Mar Theophilus School | K10: UKG | L10: Basic | M10: Offline L1-B11 Apr'26 | N10: Offline | O10: 46091 | P10: 46142 | Q10: Active | R10: 4500 | S10: 0 | T10: 0 | U10: 4500 | V10: 4500 | W10: 0 | X10: Completed | Y10: Friend Referral | Z10: Friend Referral | AA10: Https://excelkidshub.in/ | AB10: 46105.646 | AN10: Send | AO10: Email Sent
A11: A1010 | B11: Shubha Akshay Kale | C11: 9404303558 | D11: dr.shubhangipachkavde@gmail.com | E11: 29 gold coast society opposite to Atria Munjaba wasti Tingare nagar Dhanori | F11: Pune | G11: Saavi Akshay Kale | H11: 6 | I11: Female | J11: bai najamai nosherwan dastur primary school | K11: 1 | L11: Advanced | M11: Online L2-B8 Apr'26 | N11: Online | O11: 46091 | P11: 46167 | Q11: Active | R11: 6500 | S11: 0 | T11: 0 | U11: 6500 | V11: 6500 | W11: 0 | X11: Completed | Y11: Friend Referral | Z11: Friend Referral | AA11: Https://excelkidshub.in/ | AB11: 46105.962
A12: A1011 | B12: Pragya Sakhare | C12: 9303586081 , 9424980082 | D12: karunasakhare0545@gmail.com | E12: Ward no. 1 himachal nager waraseoni district Balaghat | F12: Pune | G12: Pratyusha Indurkar | H12: 5 | I12: Female | J12: Keshav english school waraseoni district Balaghat mp | K12: UKG | L12: Advanced | M12: Online L2-B8 Apr'26 | N12: Online | O12: 46091 | P12: 46167 | Q12: Active | R12: 6500 | S12: 500 | T12: 0 | U12: 6000 | V12: 6000 | W12: 0 | X12: Completed | Y12: Friend Referral | Z12: Friend Referral | AA12: Https://excelkidshub.in/ | AB12: 46107.007
A13: A1012 | B13: Vishal Vaidya | C13: 9822672693 | D13: vishal.v1988@gmail.com | E13: Ganga Niwas Munjaba wasti Dhanori | F13: Pune | G13: Anika Vaidya | H13: 6 | I13: Female | J13: Erin N nagarwala | K13: 2 | L13: Advanced | N13: Offline | O13: 46091 | P13: 46157 | Q13: Active | R13: 0 | S13: 0 | T13: 0 | U13: 0 | V13: =IF(A13="","",SUMIF(payments!B:B,A13,payments!D:D)) | W13: 0 | X13: Not Started | Y13: Friend Referral | Z13: Friend Referral | AA13: Https://excelkidshub.in/ | AB13: 46111.495
A14: A1013 | B14: Vishal Vaidya | C14: 9822672693 | D14: vishal.v1988@gmail.com | E14: Ganga Niwas Munjaba wasti Dhanori | F14: Pune | G14: Vivaan Vaidya | H14: 9 | I14: Male | J14: KV BEG | K14: 4 | L14: Advanced | N14: Offline | O14: 46091 | P14: 46157 | Q14: Active | R14: 0 | S14: 0 | T14: 0 | U14: 0 | V14: =IF(A14="","",SUMIF(payments!B:B,A14,payments!D:D)) | W14: 0 | X14: Not Started | Y14: Friend Referral | Z14: Friend Referral | AA14: Https://forms.zohopublic.in/excelkidshubzoho1/form/parentenquiryformexcelkidshubphonicsacademy/thankyou/formperma/eoaa5qfag8-0p2dnh5dgzpadjzllhkthogwpbgu7tza | AB14: 46111.497
A15: A1014 | B15: Pranjal Chincholkar | C15: 9373304880 | D15: pranjalchincholkar90@gmail.com | E15: Bhawani Prasad plot no 10, Ramchandra Nagar Lohegaon Khandve Nagar | F15: Pune | G15: Anvi Prasad Chincholkar | H15: 5 | I15: Female | J15: St. Anne's high school | K15: UKG | L15: Basic | N15: Online | O15: 46091 | P15: 46142 | Q15: Active | R15: 0 | S15: 0 | T15: 0 | U15: 0 | V15: =IF(A15="","",SUMIF(payments!B:B,A15,payments!D:D)) | W15: 0 | X15: Not Started | AB15: 46070.775
A16: A1015 | B16: Pranjal Chincholkar | C16: 9595997373 | D16: pranjalchincholkar90@gmail.com | E16: Bhavani Prasad ,plot no.10 lane 4, Ramchandra Nagar Lohegaon Khandve Nagar | F16: Pune | G16: Anvi Prasad Chincholkar | H16: 5 | I16: Female | J16: St Anne's primary school | K16: UKG | L16: Basic | N16: Online | O16: 46091 | P16: 46142 | Q16: Active | R16: 2000 | S16: 0 | T16: 0 | U16: 2000 | V16: =IF(A16="","",SUMIF(payments!B:B,A16,payments!D:D)) | W16: 2000 | X16: Not Started | Y16: From Google search | AB16: 46070.781
A17: A1016 | B17: Sachin Raghunath Kerlekar | C17: 9975440824 | D17: sachin.kerlekar@gmail.com | E17: FN.A21, Castle CHS, Viman Nagar | F17: Pune | G17: Saireesh Sachin Kerlekar | H17: 9 | I17: Male | J17: Narayana Etechno Wagholi | K17: 3 | L17: Basic | N17: Online | O17: 46091 | P17: 46142 | Q17: Active | R17: 6500 | S17: 0 | T17: 0 | U17: 6500 | V17: =IF(A17="","",SUMIF(payments!B:B,A17,payments!D:D)) | W17: 6500 | X17: Not Started | Y17: Friend Referral | Z17: Friend Referral | AB17: 46074.872
A18: A1017 | B18: Sandeep Sharma | C18: 8411009381 | D18: seaya.sharma@gmail.com | E18: Flat 410, Wing F, Gini Belvista, Dhanori | F18: Pune | G18: Seaya Sharma | H18: 4 | I18: Female | J18: VK Patil | K18: LKG | L18: Advanced | N18: Offline | O18: 46091 | P18: 46157 | Q18: Active | R18: 8500 | S18: 0 | T18: 0 | U18: 8500 | V18: =IF(A18="","",SUMIF(payments!B:B,A18,payments!D:D)) | W18: 8500 | X18: Not Started | Y18: Friend Referral | Z18: Friend Referral | AB18: 46076.654
A19: A1018 | B19: Ashish Raghunath Mhasitkar | C19: 9823199271 | D19: ashish.mhasitkar@gmail.com | E19: Mayur Kilbil Society, Dhanori, Pune | F19: Pune | G19: Siddhi Ashish Mhasitkar | H19: 9 | I19: Female | J19: Neuron Labs Dhanori Pune | K19: 3rd | L19: Advanced | N19: Online | O19: 46091 | P19: 46167 | Q19: Active | R19: 6500 | S19: 0 | T19: 0 | U19: 6500 | V19: =IF(A19="","",SUMIF(payments!B:B,A19,payments!D:D)) | W19: 6500 | X19: Not Started | Y19: Friend Referral | Z19: Friend Referral | AB19: 46078.777
A20: A1019 | B20: Ridhima Khera | C20: 9818065684 | D20: riddhmaakhera@gmail.com | E20: E801, satellite towers, Koregaon park , Pune | F20: Pune | G20: Ranveer Kumar | H20: 6 | I20: Male | J20: Billabong international school | K20: 1 | L20: Basic | N20: Online | O20: 46091 | P20: 46142 | Q20: Active | R20: 6500 | S20: 0 | T20: 0 | U20: 6500 | V20: =IF(A20="","",SUMIF(payments!B:B,A20,payments!D:D)) | W20: 6500 | X20: Not Started | Y20: Friend Referral | Z20: Friend Referral | AA20: Https://excelkidshub.in/ | AB20: 46080.716
A21: A1020 | B21: Pratik Gawande | C21: 8087950720 | D21: pratikgd.gawande@gmail.com | E21: 411,Skyways Harmony, Lohegaon | F21: Pune | G21: Nihira Pratik Gawnde | H21: 6 | I21: Female | J21: SSWS | K21: 1 | L21: Basic | N21: Offline | O21: 46091 | P21: 46142 | Q21: Active | R21: 4000 | S21: 0 | T21: 0 | U21: 4000 | V21: =IF(A21="","",SUMIF(payments!B:B,A21,payments!D:D)) | W21: 4000 | X21: Not Started | Y21: Friend Referral | Z21: Friend Referral | AA21: Https://excelkidshub.in/ | AB21: 46082.374
A22: A1021 | B22: Neha Garole | C22: 7507135334 | D22: nehajadhav.22081992@gmail.com | E22: Laxmi nagar dhanori,pune | F22: Pune | G22: Advik Garole | H22: 6 | I22: Male | J22: Mounts and patrick school | K22: Ukg | L22: Advanced | M22: Offline L2-B10 Apr'26 | N22: Offline | O22: 46091 | P22: 46157 | Q22: Active | R22: 6500 | S22: 0 | T22: 0 | U22: 6500 | V22: 3500 | W22: 3000 | X22: Partial | Y22: Friend Referral | Z22: Friend Referral | AA22: Https://excelkidshub.in/ | AB22: 46082.973
A23: A1022 | B23: Basera Waseem Shiledar | C23: 8459403684 | D23: basera.shiledar@gmail.com | E23: Khizra appartment, flat no 301,behind Bharat dhaba,next to ganga aria,dhanori pune | F23: Pune | G23: Zikra Waseem Shiledar | H23: 7 | I23: Female | J23: Nagarwala day school | K23: 1.0 | L23: Advanced | N23: Offline | O23: 46091 | P23: 46157 | Q23: Active | R23: 0 | S23: 0 | T23: 0 | U23: 0 | V23: =IF(A23="","",SUMIF(payments!B:B,A23,payments!D:D)) | W23: 0 | X23: Not Started | AA23: Https://excelkidshub.in/ | AB23: 46082.978
A24: A1023 | B24: Prashant Jadhav | C24: 9623116887 | D24: prshntjdhv707@gmail.com | E24: Jijai building kalwad | F24: Pune | G24: Naitvik Prashant Jadhav | H24: 6 | I24: Male | J24: Asha Vidyalaya | K24: UKG | L24: Basic | N24: Offline | O24: 46091 | P24: 46142 | Q24: Active | R24: 4000 | S24: 0 | T24: 0 | U24: 4000 | V24: =IF(A24="","",SUMIF(payments!B:B,A24,payments!D:D)) | W24: 4000 | X24: Not Started | Y24: Friend Referral | Z24: Friend Referral | AA24: Https://excelkidshub.in/ | AB24: 46083.974
A25: A1024 | B25: Sanjay Pralhad Dandge | C25: 9960732603 | D25: sanjay.dandge1986@gmail.com | E25: Goodwill Nirmiti, B-902, Bharat Mata Road, Lohegaon | F25: Pune | G25: Kaivalya Sanjay Dandge | H25: 8 | I25: Male | J25: Dr. Mar Theophilus School, Dhanori, Pune | K25: 3rd | L25: Advanced | M25: Offline L2-B10 Apr'26 | N25: Offline | O25: 46091 | P25: 46157 | Q25: Active | R25: 6500 | S25: 500 | T25: 0 | U25: 6000 | V25: 6000 | W25: 0 | X25: Completed | Y25: Social Media | AA25: Https://excelkidshub.in/ | AB25: 46085.494
A26: A1025 | B26: Akanksha Saurabh Sharma | C26: 91309901171 | D26: joshiakanksha27@gmail.com | E26: A103 zest county, lohegaon | F26: Pune | G26: Nishtha Sharma | H26: 4 | I26: Female | J26: DYPIS | K26: Jr.Kg | L26: Basic | N26: Offline | O26: 46091 | P26: 46142 | Q26: Active | R26: 4000 | S26: 0 | T26: 0 | U26: 4000 | V26: =IF(A26="","",SUMIF(payments!B:B,A26,payments!D:D)) | W26: 4000 | X26: Not Started | Y26: Google | AA26: Https://excelkidshub.in/ | AB26: 46085.57
A27: A1026 | B27: Dolly Oza | C27: 8087923331 | D27: dollyoza43@gmail.com | E27: Hari om sadan, lane no 4/1 ,sr. No 256/2, Khesepark | F27: Pune | G27: Rhythm Sharma | H27: 5 | I27: Female | J27: Dr. Mar Theophilus School | K27: UKG | L27: Advanced | N27: Online | O27: 46091 | P27: 46167 | Q27: Active | R27: 6000 | S27: 0 | T27: 0 | U27: 6000 | V27: =IF(A27="","",SUMIF(payments!B:B,A27,payments!D:D)) | W27: 6000 | X27: Not Started | Y27: Google | AA27: Https://excelkidshub.in/ | AB27: 46085.665
A28: A1027 | B28: Shilpa Nitin Amgaonkar | C28: 9130824959 | D28: nikhare.shilpa@gmail.com | E28: F703,Gini Belvista DN Parande Park Dhanori Pune | F28: Pune | G28: Shivansh Nitin Amgaonkar | H28: 4 | I28: Male | J28: Vikhe Patil Memorial School | K28: Jr KG | L28: Basic | N28: Offline | O28: 46091 | P28: 46142 | Q28: Active | R28: 4000 | S28: 0 | T28: 0 | U28: 4000 | V28: =IF(A28="","",SUMIF(payments!B:B,A28,payments!D:D)) | W28: 4000 | X28: Not Started | Y28: Friend Referral | Z28: Friend Referral | AA28: Https://excelkidshub.in/ | AB28: 46085.768
A29: A1028 | B29: Radhika Abhijeet Mancharkar | C29: 9763783687 | D29: radhika.narwaria@gmail.com | E29: Flat no 204, Ameya lotus near Brezza society, dhanori road dhanori Pune 411015 | F29: Pune | G29: Virat Abhijeet Mancharkar | H29: 7 | I29: Male | J29: Neuron labs | K29: 2 nd class | L29: Advanced | M29: Online L2-B8 Apr'26 | N29: Online | O29: 46091 | P29: 46167 | Q29: Active | R29: 6500 | S29: 0 | T29: 0 | U29: 6500 | V29: 500 | W29: 6000 | X29: Partial | Y29: Friend Referral | Z29: Friend Referral | AB29: 46085.825
A30: A1029 | B30: Aboli Akshay Kulkarni | C30: 9309768090 | D30: aboliofficial007@gmail.com | E30: C 304 goodwill breeza dhanori | F30: Pune | G30: Aarunya Akshay Kulkarni | H30: 6 | I30: Female | J30: Fun n Fun | K30: UKG | L30: Advanced | N30: Offline | O30: 46091 | P30: 46157 | Q30: Active | R30: 8500 | S30: 0 | T30: 0 | U30: 8500 | V30: =IF(A30="","",SUMIF(payments!B:B,A30,payments!D:D)) | W30: 8500 | X30: Not Started | Y30: Friend Referral | Z30: Friend Referral | AA30: Https://excelkidshub.in/ | AB30: 46085.996
A31: A1030 | B31: Sakina Shaikh | C31: 9850604858 | D31: ssakina0217@gmail.com | E31: C1-302, Goodwill Orchid | F31: Pune | G31: Riana Selvaraj | H31: 7 | I31: Female | J31: The Bishop's | K31: 2 | L31: Advanced | N31: Offline | O31: 46091 | P31: 46157 | Q31: Active | R31: 0 | S31: 0 | T31: 0 | U31: 0 | V31: =IF(A31="","",SUMIF(payments!B:B,A31,payments!D:D)) | W31: 0 | X31: Not Started | Y31: Social Media | AA31: Https://excelkidshub.in/ | AB31: 46086.531
A32: A1031 | B32: Sakina Shaikh | C32: 9850604858 | D32: ssakina0217@gmail.com | E32: C1-302, Goodwill Orchid | F32: Pune | G32: Rian Selvaraj | H32: 7 | I32: Male | J32: The Bishop's | K32: 2 | L32: Advanced | N32: Offline | O32: 46091 | P32: 46157 | Q32: Active | R32: 0 | S32: 0 | T32: 0 | U32: 0 | V32: =IF(A32="","",SUMIF(payments!B:B,A32,payments!D:D)) | W32: 0 | X32: Not Started | Y32: Social Media | AA32: Https://forms.zohopublic.in/excelkidshubzoho1/form/parentenquiryformexcelkidshubphonicsacademy/thankyou/formperma/eoaa5qfag8-0p2dnh5dgzpadjzllhkthogwpbgu7tza | AB32: 46086.532
A33: A1032 | B33: Reema Mishra | C33: 7798814805 | D33: reema.miahra20@gmail.com | E33: Khese park | F33: Pune | G33: Reesha Tiwari | H33: 6 | I33: Female | J33: D Y Patil | K33: Sr kg | L33: Advanced | N33: Online | O33: 46091 | P33: 46167 | Q33: Active | R33: 6000 | S33: 0 | T33: 0 | U33: 6000 | V33: =IF(A33="","",SUMIF(payments!B:B,A33,payments!D:D)) | W33: 6000 | X33: Not Started | Y33: Friend Referral | Z33: Friend Referral | AA33: Https://excelkidshub.in/ | AB33: 46086.536
A34: A1033 | B34: Manali Yavalkar | C34: 8976344256 | D34: manali.yavalkar@gmail.com | E34: A1-1401, Nyati Elysia river front road Kharadi | F34: Pune | G34: Anay Sanket Yavalkar | H34: 7 | I34: Male | J34: Euro school Kharadi | K34: 1 | L34: Advanced | N34: Online | O34: 46091 | P34: 46167 | Q34: Active | R34: 6500 | S34: 0 | T34: 0 | U34: 6500 | V34: =IF(A34="","",SUMIF(payments!B:B,A34,payments!D:D)) | W34: 6500 | X34: Not Started | Y34: Social Media | AA34: Https://excelkidshub.in/ | AB34: 46086.549
A35: A1034 | B35: Dr. Kashmira | C35: 9130028028 | D35: drkashmiralonkar@gmail.com | E35: Ehsaas villa plot no 25 S. No 253/A shivaji Maharaj Road khese park lohegaon Road Pune | F35: Pune | G35: Mannwah Kawale | H35: 6 | I35: Female | J35: DMTS | K35: Ukg | L35: Advanced | M35: Offline L2-B10 Apr'26 | N35: Offline | O35: 46091 | P35: 46157 | Q35: Active | R35: 6500 | S35: 0 | T35: 0 | U35: 6500 | V35: =IF(A35="","",SUMIF(payments!B:B,A35,payments!D:D)) | W35: 6500 | X35: Not Started | Y35: Friend Referral | Z35: Friend Referral | AA35: Https://excelkidshub.in/ | AB35: 46086.956
A36: A1035 | B36: Shruti Sehgal | C36: 9049324573 | D36: shrutisehgal29@gmail.com | E36: B-102 Vivanta Life Vishakha | F36: Pune | G36: Viaan Singh | H36: 6 | I36: Male | J36: Sanskriti | K36: 2.0 | L36: Advanced | N36: Offline | O36: 46091 | P36: 46157 | Q36: Active | R36: 0 | S36: 0 | T36: 0 | U36: 0 | V36: =IF(A36="","",SUMIF(payments!B:B,A36,payments!D:D)) | W36: 0 | X36: Not Started | Y36: Friend Referral | Z36: Friend Referral | AA36: Https://excelkidshub.in/ | AB36: 46088.425
A37: A1036 | B37: Yogendra Uttam Londhe | C37: 9552580236 | D37: saylikamble16@gmail.com | E37: 402,vaman residency sector 21 ghansoli | F37: Pune | G37: Eehita Yogendra Londhe | H37: 6 | I37: Female | J37: DAV airoli | K37: 1.0 | L37: Basic | N37: Online | O37: 46091 | P37: 46142 | Q37: Active | R37: 4500 | S37: 0 | T37: 0 | U37: 4500 | V37: =IF(A37="","",SUMIF(payments!B:B,A37,payments!D:D)) | W37: 4500 | X37: Not Started | Y37: Social Media | AA37: Https://excelkidshub.in/ | AB37: 46088.64
A38: A1037 | B38: Anurag Dattatreya Jagdhane | C38: 9766410479 | D38: snhfstfd@gmail.com | E38: B301 Vivanata life Vishakha | F38: Pune | G38: Amogh Jagdhane | H38: 4 | I38: Male | J38: St Mary's | K38: Nursary | L38: Basic | N38: Offline | O38: 46091 | P38: 46142 | Q38: Active | R38: 4500 | S38: 0 | T38: 0 | U38: 4500 | V38: 4500 | W38: 0 | X38: Completed | Y38: Friend Referral | Z38: Friend Referral | AA38: Https://excelkidshub.in/ | AB38: 46088.69 | AN38: Send | AO38: Not Sent - Payment not completed
A39: A1038 | B39: Anurag Jagdhane | C39: 9766410479 | D39: snhfstfd@gmail.com | E39: B301 Vivanata life Vishakha | F39: Pune | G39: Avni Jagdhane | H39: 5 | I39: Female | J39: St Mary's | K39: LKG | L39: Basic | N39: Offline | O39: 46091 | P39: 46142 | Q39: Active | R39: 6500 | S39: 0 | T39: 0 | U39: 6500 | V39: 6500 | W39: 0 | X39: Completed | Y39: Friend Referral | Z39: Friend Referral | AA39: Https://forms.zohopublic.in/excelkidshubzoho1/form/parentenquiryformexcelkidshubphonicsacademy/thankyou/formperma/eoaa5qfag8-0p2dnh5dgzpadjzllhkthogwpbgu7tza | AB39: 46088.691 | AN39: Send | AO39: Email Sent
A40: A1039 | B40: Sabna | C40: 971558413265 | D40: sabnasivanandan21@gmail.com | E40: Thazhath house anchery thrissur keraala | F40: Pune | G40: Aniketh | H40: 9 | I40: Male | J40: Indian high school | K40: 3.0 | L40: Advanced | N40: Online | O40: 46091 | P40: 46167 | Q40: Active | R40: 6500 | S40: 0 | T40: 0 | U40: 6500 | V40: =IF(A40="","",SUMIF(payments!B:B,A40,payments!D:D)) | W40: 6500 | X40: Not Started | Y40: Social Media | AA40: Https://excelkidshub.in/ | AB40: 46089.047
...

Sheet Teachers_Training

Sheet payments
A1: Payment ID | B1: Admission ID | C1: Payment Date | D1: Amount Paid | E1: Payment Mode | F1: Transaction ID | G1: Notes
A2: PAY001 | B2: A001 | C2: 46097.808 | D2: 4500 | E2: Direct
A3: PAY002 | B3: A002 | C3: 46097.869 | D3: 8500 | E3: Direct | G3: English communication and handwriting
A4: PAY003 | B4: A004 | C4: 46098.794 | D4: 4500 | E4: Direct | G4: Yas
A5: PAY004 | B5: A015 | C5: 46070.931 | D5: 2000 | E5: Direct
A6: PAY005 | B6: A016 | C6: 46090.527 | D6: 6500 | E6: Direct | G6: Looking for his reading and spelling creation improvement
A7: PAY006 | B7: A017 | C7: 46096.001 | D7: 8500 | E7: Direct
A8: PAY007 | B8: A018 | C8: 46089.948 | D8: 6500 | E8: Direct
A9: PAY008 | B9: A019 | C9: 46090.572 | D9: 6500 | E9: Direct
A10: PAY009 | B10: A020 | C10: 46090.962 | D10: 4000 | E10: Direct
A11: PAY010 | B11: A023 | C11: 46090.963 | D11: 4000 | E11: Direct
A12: PAY011 | B12: A025 | C12: 46090.571 | D12: 4000 | E12: Direct
A13: PAY012 | B13: A026 | C13: 46092.773 | D13: 6000 | E13: Direct
A14: PAY013 | B14: A027 | C14: 46093.671 | D14: 4000 | E14: Direct
A15: PAY014 | B15: A029 | C15: 46090.799 | D15: 6500 | E15: Direct
A16: PAY015 | B16: A030 | C16: 46093.671 | D16: 8500 | E16: Direct | G16: Spoken English-basic day to day life useful.
A17: PAY016 | B17: A033 | C17: 46086.563 | D17: 6000 | E17: Direct
A18: PAY017 | B18: A034 | C18: 46090.543 | D18: 6500 | E18: Direct
A19: PAY018 | B19: A037 | C19: 46098.385 | D19: 4500 | E19: Direct
A20: PAY019 | B20: A040 | C20: 46090.383 | D20: 6500 | E20: Direct
A21: PAY020 | B21: A041 | C21: 46097.54 | D21: 4500 | E21: Direct | G21: Please make him speak a lot and pls focus on his pronounciation
A22: PAY021 | B22: A042 | C22: 46090.522 | D22: 6500 | E22: Direct
A23: PAY022 | B23: A043 | C23: 46090.572 | D23: 6500 | E23: Direct
A24: PAY023 | B24: A046 | C24: 46097.556 | D24: 4000 | E24: Direct
A25: PAY024 | B25: A047 | C25: 46111.967 | D25: 8500 | E25: Direct | G25: No such requirements but on daily basis give him homework so that whatever has been taught remains in his mind and give updates of whatever taught in the class so that we can take revision at home.
A26: PAY025 | B26: A048 | C26: 46097.809 | D26: 4500 | E26: Direct
A27: PAY026 | B27: A050 | C27: 46098.437 | D27: 4500 | E27: Direct
A28: PAY027 | B28: A052 | C28: 46094.691 | D28: 8000 | E28: Direct
A29: PAY028 | B29: A053 | C29: 46095.484 | D29: 4000 | E29: Direct
A30: PAY029 | B30: A056 | C30: 46095.86 | D30: 4500 | E30: Direct
A31: PAY030 | B31: A057 | C31: 46095.86 | D31: 4500 | E31: Direct
A32: P001 | B32: A059 | C32: 46121 | D32: 1000 | E32: UPI
A33: P002 | B33: A080 | C33: 46122 | E33: UPI

Sheet batches
A1: Batch Code | B1: Level | C1: Mode | D1: Start Date | E1: End Date | F1: Timing | G1: Capacity | H1: Days | I1: Teacher | J1: Sessions
A2: Online L1-B1 Jan'26 | B2: Basic | C2: Online | D2: 46091 | E2: 46142 | F2: 6:00 PM - 7:00 PM | G2: 12
A3: Offline L1-B2 Feb'26 | B3: Basic | C3: Offline | D3: 46091 | E3: 46142 | F3: 7:30 PM - 8:30 PM | G3: 12
A4: Offline L2-B3 Feb'26 | B4: Advanced | C4: Offline | D4: 46122 | E4: 46173 | F4: 6:00 PM - 7:00 PM | G4: 12
A5: Offline L2-B4 Mar'26 | B5: Advanced | C5: Offline | D5: 46143 | E5: 46174 | F5: 6:00 PM - 7:00 PM | G5: 12
A6: Offline L1-B5 Mar'26 | B6: Basic | C6: Offline | D6: 46091 | E6: 46157 | F6: 5:00 PM - 6:00 PM | G6: 12
A7: Online L2-B6 Mar'26 | B7: Advanced | C7: Online | D7: 46091 | E7: 46167 | F7: 7:30 PM - 8:30 PM | G7: 12
A8: Online L1-B7 Mar'26 | B8: Basic | C8: Online | D8: 46122 | E8: 46168 | F8: 5:00 PM - 6:00 PM | G8: 12
A9: Online L2-B8 Apr'26 | B9: Advanced | C9: Online | D9: 46122 | E9: 46168 | F9: 11:00 AM - 12:00 PM | G9: 12
A10: Offline L3-B9 Apr'26 | B10: Proficient | C10: Offline | D10: 46122 | E10: 46168 | F10: 2:30 PM - 3:30 PM | G10: 12
A11: Offline L2-B10 Apr'26 | B11: Advanced | C11: Offline | D11: 46122 | E11: 46168 | F11: 4:00 PM - 5:00 PM | G11: 12
A12: Offline L1-B11 Apr'26 | B12: Basic | C12: Offline | D12: 46122 | E12: 46168 | F12: 6:00 PM - 7:00 PM | G12: 12
A13: Offline L3-B11 Apr'26 | B13: Proficiant | C13: Online | D13: 46122 | E13: 46168 | F13: 4:00 PM - 5:00 PM | G13: 12
A14: Offline L1-B12 June'26 | B14: Basic | C14: Offline | D14: 46189 | F14: 6:00 PM - 7:00 PM | G14: 12 | H14: Tue/Thu/Sat | J14: 20-24
A15: Online L1-B13 June'26 | B15: Basic | C15: Online | D15: 46189 | F15: 7:30 PM - 8:30 PM | G15: 12 | H15: Tue/Thu/Sat | J15: 20-24
A16: Offline L2-B14 June'26 | B16: Advanced | C16: Offline | D16: 46189 | F16: 6:00 PM - 7:00 PM | G16: 12 | H16: Mon/Wed/Fri | J16: 30-35
A17: Online L2-B15 June'26 | B17: Advanced | C17: Online | D17: 46188 | F17: 7:30 PM - 8:30 PM | G17: 12 | H17: Mon/Wed/Fri | J17: 30-35
A18: Offline Reading June'26 | B18: Reading | C18: Offline | D18: 46188 | F18: 5:00 PM - 6:00 PM | G18: 12 | H18: Mon/Wed/Fri | J18: 30-35
A19: Online Teachers June'26 | B19: Teachers Training | C19: Online | D19: 46182 | F19: 1:00 PM - 3:00 PM | G19: 10 | H19: Mon–Fri | J19: 5

Sheet expenses
A1: Date | B1: Category | C1: Sub Category | D1: Amount | E1: Payment Mode | F1: Notes
A2: 45992 | B2: Printing | C2: Book | D2: 21283 | E2: Online
A3: 45992 | B3: Rent | C3: jan - Dec 2025 | D3: 55200 | E3: Online
A4: 45992 | B4: Marketing | C4: Flex Boad | D4: 5200 | E4: Online
A5: 45992 | B5: Salary | C5: Salary | D5: 16000
A6: 45992 | B6: Salary | C6: Office Boy | D6: 6000
A7: 46037 | B7: Rent | D7: 5000
A8: 46037 | B8: Printing | D8: 1050
A9: 46037 | B9: Salary | C9: salary | D9: 7000
A10: 46037 | B10: Salary | C10: Office Boy | D10: 500
A11: 46063 | B11: Printing | D11: 1865
A12: 46063 | B12: Rent | D12: 5000
A13: 46063 | B13: Salary | D13: 500
A14: 46063 | B14: Salary | D14: 7000
A15: 46083 | B15: Printing | D15: 7650
A16: 46083 | B16: Internet | C16: Website | D16: 3000
A17: 46083 | B17: Salary | D17: 0
A18: 46083 | B18: Events | C18: Chocolate | D18: 1000
A19: 46083 | B19: Miscellanious | C19: Petrol | D19: 1000

Sheet finance-summary
A1: Month | B1: Admission Count | C1: New Admissions Value | D1: Collections This Month | E1: Total Expense | F1: Profit | G1: Closing Pending | H1: Outstanding Admissions | I1: Salary Expense | J1: Marketing Expense | K1: Rent Expense | L1: Software Expense | M1: Other Expense
A2: 2026-01 | C2: =SUMPRODUCT((TEXT(admissions!$AB$2:$AB$78,"yyyy-mm")=$A2)*(admissions!$U$2:$U$78)) | D2: =SUMPRODUCT((TEXT(payments!$C$2:$C$501,"yyyy-mm")=$A2)*(payments!$D$2:$D$501)) | E2: =SUMPRODUCT((TEXT(expenses!$A$2:$A$501,"yyyy-mm")=$A2)*(expenses!$D$2:$D$501)) | F2: =D2-E2 | G2: =SUMPRODUCT((TEXT(admissions!$AB$2:$AB$78,"yyyy-mm")<=$A2)*(admissions!$W$2:$W$78)) | H2: =SUMPRODUCT((admissions!$W$2:$W$78>0)*(TEXT(admissions!$AB$2:$AB$78,"yyyy-mm")<=$A2)) | I2: =SUMPRODUCT((TEXT(expenses!$A$2:$A$501,"yyyy-mm")=$A2)*(expenses!$B$2:$B$501="Salary")*(expenses!$D$2:$D$501)) | J2: =SUMPRODUCT(((TEXT(expenses!$A$2:$A$501,"yyyy-mm")=$A2)*((expenses!$B$2:$B$501="Marketing")+(expenses!$B$2:$B$501="Advertisement")))*(expenses!$D$2:$D$501)) | K2: =SUMPRODUCT((TEXT(expenses!$A$2:$A$501,"yyyy-mm")=$A2)*(expenses!$B$2:$B$501="Rent")*(expenses!$D$2:$D$501)) | L2: =SUMPRODUCT((TEXT(expenses!$A$2:$A$501,"yyyy-mm")=$A2)*(expenses!$B$2:$B$501="Software")*(expenses!$D$2:$D$501)) | M2: =E2-I2-J2-K2-L2
A3: 2026-02 | C3: =SUMPRODUCT((TEXT(admissions!$AB$2:$AB$78,"yyyy-mm")=$A3)*(admissions!$U$2:$U$78)) | D3: =SUMPRODUCT((TEXT(payments!$C$2:$C$501,"yyyy-mm")=$A3)*(payments!$D$2:$D$501)) | E3: =SUMPRODUCT((TEXT(expenses!$A$2:$A$501,"yyyy-mm")=$A3)*(expenses!$D$2:$D$501)) | F3: =D3-E3 | G3: =SUMPRODUCT((TEXT(admissions!$AB$2:$AB$78,"yyyy-mm")<=$A3)*(admissions!$W$2:$W$78)) | H3: =SUMPRODUCT((admissions!$W$2:$W$78>0)*(TEXT(admissions!$AB$2:$AB$78,"yyyy-mm")<=$A3)) | I3: =SUMPRODUCT((TEXT(expenses!$A$2:$A$501,"yyyy-mm")=$A3)*(expenses!$B$2:$B$501="Salary")*(expenses!$D$2:$D$501)) | J3: =SUMPRODUCT(((TEXT(expenses!$A$2:$A$501,"yyyy-mm")=$A3)*((expenses!$B$2:$B$501="Marketing")+(expenses!$B$2:$B$501="Advertisement")))*(expenses!$D$2:$D$501)) | K3: =SUMPRODUCT((TEXT(expenses!$A$2:$A$501,"yyyy-mm")=$A3)*(expenses!$B$2:$B$501="Rent")*(expenses!$D$2:$D$501)) | L3: =SUMPRODUCT((TEXT(expenses!$A$2:$A$501,"yyyy-mm")=$A3)*(expenses!$B$2:$B$501="Software")*(expenses!$D$2:$D$501)) | M3: =E3-I3-J3-K3-L3
A4: 2026-03 | C4: =SUMPRODUCT((TEXT(admissions!$AB$2:$AB$78,"yyyy-mm")=$A4)*(admissions!$U$2:$U$78)) | D4: =SUMPRODUCT((TEXT(payments!$C$2:$C$501,"yyyy-mm")=$A4)*(payments!$D$2:$D$501)) | E4: =SUMPRODUCT((TEXT(expenses!$A$2:$A$501,"yyyy-mm")=$A4)*(expenses!$D$2:$D$501)) | F4: =D4-E4 | G4: =SUMPRODUCT((TEXT(admissions!$AB$2:$AB$78,"yyyy-mm")<=$A4)*(admissions!$W$2:$W$78)) | H4: =SUMPRODUCT((admissions!$W$2:$W$78>0)*(TEXT(admissions!$AB$2:$AB$78,"yyyy-mm")<=$A4)) | I4: =SUMPRODUCT((TEXT(expenses!$A$2:$A$501,"yyyy-mm")=$A4)*(expenses!$B$2:$B$501="Salary")*(expenses!$D$2:$D$501)) | J4: =SUMPRODUCT(((TEXT(expenses!$A$2:$A$501,"yyyy-mm")=$A4)*((expenses!$B$2:$B$501="Marketing")+(expenses!$B$2:$B$501="Advertisement")))*(expenses!$D$2:$D$501)) | K4: =SUMPRODUCT((TEXT(expenses!$A$2:$A$501,"yyyy-mm")=$A4)*(expenses!$B$2:$B$501="Rent")*(expenses!$D$2:$D$501)) | L4: =SUMPRODUCT((TEXT(expenses!$A$2:$A$501,"yyyy-mm")=$A4)*(expenses!$B$2:$B$501="Software")*(expenses!$D$2:$D$501)) | M4: =E4-I4-J4-K4-L4
A5: 2026-04 | C5: =SUMPRODUCT((TEXT(admissions!$AB$2:$AB$78,"yyyy-mm")=$A5)*(admissions!$U$2:$U$78)) | D5: =SUMPRODUCT((TEXT(payments!$C$2:$C$501,"yyyy-mm")=$A5)*(payments!$D$2:$D$501)) | E5: =SUMPRODUCT((TEXT(expenses!$A$2:$A$501,"yyyy-mm")=$A5)*(expenses!$D$2:$D$501)) | F5: =D5-E5 | G5: =SUMPRODUCT((TEXT(admissions!$AB$2:$AB$78,"yyyy-mm")<=$A5)*(admissions!$W$2:$W$78)) | H5: =SUMPRODUCT((admissions!$W$2:$W$78>0)*(TEXT(admissions!$AB$2:$AB$78,"yyyy-mm")<=$A5)) | I5: =SUMPRODUCT((TEXT(expenses!$A$2:$A$501,"yyyy-mm")=$A5)*(expenses!$B$2:$B$501="Salary")*(expenses!$D$2:$D$501)) | J5: =SUMPRODUCT(((TEXT(expenses!$A$2:$A$501,"yyyy-mm")=$A5)*((expenses!$B$2:$B$501="Marketing")+(expenses!$B$2:$B$501="Advertisement")))*(expenses!$D$2:$D$501)) | K5: =SUMPRODUCT((TEXT(expenses!$A$2:$A$501,"yyyy-mm")=$A5)*(expenses!$B$2:$B$501="Rent")*(expenses!$D$2:$D$501)) | L5: =SUMPRODUCT((TEXT(expenses!$A$2:$A$501,"yyyy-mm")=$A5)*(expenses!$B$2:$B$501="Software")*(expenses!$D$2:$D$501)) | M5: =E5-I5-J5-K5-L5
A6: 2026-05 | C6: =SUMPRODUCT((TEXT(admissions!$AB$2:$AB$78,"yyyy-mm")=$A6)*(admissions!$U$2:$U$78)) | D6: =SUMPRODUCT((TEXT(payments!$C$2:$C$501,"yyyy-mm")=$A6)*(payments!$D$2:$D$501)) | E6: =SUMPRODUCT((TEXT(expenses!$A$2:$A$501,"yyyy-mm")=$A6)*(expenses!$D$2:$D$501)) | F6: =D6-E6 | G6: =SUMPRODUCT((TEXT(admissions!$AB$2:$AB$78,"yyyy-mm")<=$A6)*(admissions!$W$2:$W$78)) | H6: =SUMPRODUCT((admissions!$W$2:$W$78>0)*(TEXT(admissions!$AB$2:$AB$78,"yyyy-mm")<=$A6)) | I6: =SUMPRODUCT((TEXT(expenses!$A$2:$A$501,"yyyy-mm")=$A6)*(expenses!$B$2:$B$501="Salary")*(expenses!$D$2:$D$501)) | J6: =SUMPRODUCT(((TEXT(expenses!$A$2:$A$501,"yyyy-mm")=$A6)*((expenses!$B$2:$B$501="Marketing")+(expenses!$B$2:$B$501="Advertisement")))*(expenses!$D$2:$D$501)) | K6: =SUMPRODUCT((TEXT(expenses!$A$2:$A$501,"yyyy-mm")=$A6)*(expenses!$B$2:$B$501="Rent")*(expenses!$D$2:$D$501)) | L6: =SUMPRODUCT((TEXT(expenses!$A$2:$A$501,"yyyy-mm")=$A6)*(expenses!$B$2:$B$501="Software")*(expenses!$D$2:$D$501)) | M6: =E6-I6-J6-K6-L6
A7: 2026-06 | C7: =SUMPRODUCT((TEXT(admissions!$AB$2:$AB$78,"yyyy-mm")=$A7)*(admissions!$U$2:$U$78)) | D7: =SUMPRODUCT((TEXT(payments!$C$2:$C$501,"yyyy-mm")=$A7)*(payments!$D$2:$D$501)) | E7: =SUMPRODUCT((TEXT(expenses!$A$2:$A$501,"yyyy-mm")=$A7)*(expenses!$D$2:$D$501)) | F7: =D7-E7 | G7: =SUMPRODUCT((TEXT(admissions!$AB$2:$AB$78,"yyyy-mm")<=$A7)*(admissions!$W$2:$W$78)) | H7: =SUMPRODUCT((admissions!$W$2:$W$78>0)*(TEXT(admissions!$AB$2:$AB$78,"yyyy-mm")<=$A7)) | I7: =SUMPRODUCT((TEXT(expenses!$A$2:$A$501,"yyyy-mm")=$A7)*(expenses!$B$2:$B$501="Salary")*(expenses!$D$2:$D$501)) | J7: =SUMPRODUCT(((TEXT(expenses!$A$2:$A$501,"yyyy-mm")=$A7)*((expenses!$B$2:$B$501="Marketing")+(expenses!$B$2:$B$501="Advertisement")))*(expenses!$D$2:$D$501)) | K7: =SUMPRODUCT((TEXT(expenses!$A$2:$A$501,"yyyy-mm")=$A7)*(expenses!$B$2:$B$501="Rent")*(expenses!$D$2:$D$501)) | L7: =SUMPRODUCT((TEXT(expenses!$A$2:$A$501,"yyyy-mm")=$A7)*(expenses!$B$2:$B$501="Software")*(expenses!$D$2:$D$501)) | M7: =E7-I7-J7-K7-L7
A8: 2026-07 | C8: =SUMPRODUCT((TEXT(admissions!$AB$2:$AB$78,"yyyy-mm")=$A8)*(admissions!$U$2:$U$78)) | D8: =SUMPRODUCT((TEXT(payments!$C$2:$C$501,"yyyy-mm")=$A8)*(payments!$D$2:$D$501)) | E8: =SUMPRODUCT((TEXT(expenses!$A$2:$A$501,"yyyy-mm")=$A8)*(expenses!$D$2:$D$501)) | F8: =D8-E8 | G8: =SUMPRODUCT((TEXT(admissions!$AB$2:$AB$78,"yyyy-mm")<=$A8)*(admissions!$W$2:$W$78)) | H8: =SUMPRODUCT((admissions!$W$2:$W$78>0)*(TEXT(admissions!$AB$2:$AB$78,"yyyy-mm")<=$A8)) | I8: =SUMPRODUCT((TEXT(expenses!$A$2:$A$501,"yyyy-mm")=$A8)*(expenses!$B$2:$B$501="Salary")*(expenses!$D$2:$D$501)) | J8: =SUMPRODUCT(((TEXT(expenses!$A$2:$A$501,"yyyy-mm")=$A8)*((expenses!$B$2:$B$501="Marketing")+(expenses!$B$2:$B$501="Advertisement")))*(expenses!$D$2:$D$501)) | K8: =SUMPRODUCT((TEXT(expenses!$A$2:$A$501,"yyyy-mm")=$A8)*(expenses!$B$2:$B$501="Rent")*(expenses!$D$2:$D$501)) | L8: =SUMPRODUCT((TEXT(expenses!$A$2:$A$501,"yyyy-mm")=$A8)*(expenses!$B$2:$B$501="Software")*(expenses!$D$2:$D$501)) | M8: =E8-I8-J8-K8-L8
A9: 2026-08 | C9: =SUMPRODUCT((TEXT(admissions!$AB$2:$AB$78,"yyyy-mm")=$A9)*(admissions!$U$2:$U$78)) | D9: =SUMPRODUCT((TEXT(payments!$C$2:$C$501,"yyyy-mm")=$A9)*(payments!$D$2:$D$501)) | E9: =SUMPRODUCT((TEXT(expenses!$A$2:$A$501,"yyyy-mm")=$A9)*(expenses!$D$2:$D$501)) | F9: =D9-E9 | G9: =SUMPRODUCT((TEXT(admissions!$AB$2:$AB$78,"yyyy-mm")<=$A9)*(admissions!$W$2:$W$78)) | H9: =SUMPRODUCT((admissions!$W$2:$W$78>0)*(TEXT(admissions!$AB$2:$AB$78,"yyyy-mm")<=$A9)) | I9: =SUMPRODUCT((TEXT(expenses!$A$2:$A$501,"yyyy-mm")=$A9)*(expenses!$B$2:$B$501="Salary")*(expenses!$D$2:$D$501)) | J9: =SUMPRODUCT(((TEXT(expenses!$A$2:$A$501,"yyyy-mm")=$A9)*((expenses!$B$2:$B$501="Marketing")+(expenses!$B$2:$B$501="Advertisement")))*(expenses!$D$2:$D$501)) | K9: =SUMPRODUCT((TEXT(expenses!$A$2:$A$501,"yyyy-mm")=$A9)*(expenses!$B$2:$B$501="Rent")*(expenses!$D$2:$D$501)) | L9: =SUMPRODUCT((TEXT(expenses!$A$2:$A$501,"yyyy-mm")=$A9)*(expenses!$B$2:$B$501="Software")*(expenses!$D$2:$D$501)) | M9: =E9-I9-J9-K9-L9
A10: 2026-09 | C10: =SUMPRODUCT((TEXT(admissions!$AB$2:$AB$78,"yyyy-mm")=$A10)*(admissions!$U$2:$U$78)) | D10: =SUMPRODUCT((TEXT(payments!$C$2:$C$501,"yyyy-mm")=$A10)*(payments!$D$2:$D$501)) | E10: =SUMPRODUCT((TEXT(expenses!$A$2:$A$501,"yyyy-mm")=$A10)*(expenses!$D$2:$D$501)) | F10: =D10-E10 | G10: =SUMPRODUCT((TEXT(admissions!$AB$2:$AB$78,"yyyy-mm")<=$A10)*(admissions!$W$2:$W$78)) | H10: =SUMPRODUCT((admissions!$W$2:$W$78>0)*(TEXT(admissions!$AB$2:$AB$78,"yyyy-mm")<=$A10)) | I10: =SUMPRODUCT((TEXT(expenses!$A$2:$A$501,"yyyy-mm")=$A10)*(expenses!$B$2:$B$501="Salary")*(expenses!$D$2:$D$501)) | J10: =SUMPRODUCT(((TEXT(expenses!$A$2:$A$501,"yyyy-mm")=$A10)*((expenses!$B$2:$B$501="Marketing")+(expenses!$B$2:$B$501="Advertisement")))*(expenses!$D$2:$D$501)) | K10: =SUMPRODUCT((TEXT(expenses!$A$2:$A$501,"yyyy-mm")=$A10)*(expenses!$B$2:$B$501="Rent")*(expenses!$D$2:$D$501)) | L10: =SUMPRODUCT((TEXT(expenses!$A$2:$A$501,"yyyy-mm")=$A10)*(expenses!$B$2:$B$501="Software")*(expenses!$D$2:$D$501)) | M10: =E10-I10-J10-K10-L10
A11: 2026-10 | C11: =SUMPRODUCT((TEXT(admissions!$AB$2:$AB$78,"yyyy-mm")=$A11)*(admissions!$U$2:$U$78)) | D11: =SUMPRODUCT((TEXT(payments!$C$2:$C$501,"yyyy-mm")=$A11)*(payments!$D$2:$D$501)) | E11: =SUMPRODUCT((TEXT(expenses!$A$2:$A$501,"yyyy-mm")=$A11)*(expenses!$D$2:$D$501)) | F11: =D11-E11 | G11: =SUMPRODUCT((TEXT(admissions!$AB$2:$AB$78,"yyyy-mm")<=$A11)*(admissions!$W$2:$W$78)) | H11: =SUMPRODUCT((admissions!$W$2:$W$78>0)*(TEXT(admissions!$AB$2:$AB$78,"yyyy-mm")<=$A11)) | I11: =SUMPRODUCT((TEXT(expenses!$A$2:$A$501,"yyyy-mm")=$A11)*(expenses!$B$2:$B$501="Salary")*(expenses!$D$2:$D$501)) | J11: =SUMPRODUCT(((TEXT(expenses!$A$2:$A$501,"yyyy-mm")=$A11)*((expenses!$B$2:$B$501="Marketing")+(expenses!$B$2:$B$501="Advertisement")))*(expenses!$D$2:$D$501)) | K11: =SUMPRODUCT((TEXT(expenses!$A$2:$A$501,"yyyy-mm")=$A11)*(expenses!$B$2:$B$501="Rent")*(expenses!$D$2:$D$501)) | L11: =SUMPRODUCT((TEXT(expenses!$A$2:$A$501,"yyyy-mm")=$A11)*(expenses!$B$2:$B$501="Software")*(expenses!$D$2:$D$501)) | M11: =E11-I11-J11-K11-L11
A12: 2026-11 | C12: =SUMPRODUCT((TEXT(admissions!$AB$2:$AB$78,"yyyy-mm")=$A12)*(admissions!$U$2:$U$78)) | D12: =SUMPRODUCT((TEXT(payments!$C$2:$C$501,"yyyy-mm")=$A12)*(payments!$D$2:$D$501)) | E12: =SUMPRODUCT((TEXT(expenses!$A$2:$A$501,"yyyy-mm")=$A12)*(expenses!$D$2:$D$501)) | F12: =D12-E12 | G12: =SUMPRODUCT((TEXT(admissions!$AB$2:$AB$78,"yyyy-mm")<=$A12)*(admissions!$W$2:$W$78)) | H12: =SUMPRODUCT((admissions!$W$2:$W$78>0)*(TEXT(admissions!$AB$2:$AB$78,"yyyy-mm")<=$A12)) | I12: =SUMPRODUCT((TEXT(expenses!$A$2:$A$501,"yyyy-mm")=$A12)*(expenses!$B$2:$B$501="Salary")*(expenses!$D$2:$D$501)) | J12: =SUMPRODUCT(((TEXT(expenses!$A$2:$A$501,"yyyy-mm")=$A12)*((expenses!$B$2:$B$501="Marketing")+(expenses!$B$2:$B$501="Advertisement")))*(expenses!$D$2:$D$501)) | K12: =SUMPRODUCT((TEXT(expenses!$A$2:$A$501,"yyyy-mm")=$A12)*(expenses!$B$2:$B$501="Rent")*(expenses!$D$2:$D$501)) | L12: =SUMPRODUCT((TEXT(expenses!$A$2:$A$501,"yyyy-mm")=$A12)*(expenses!$B$2:$B$501="Software")*(expenses!$D$2:$D$501)) | M12: =E12-I12-J12-K12-L12
A13: 2026-12 | C13: =SUMPRODUCT((TEXT(admissions!$AB$2:$AB$78,"yyyy-mm")=$A13)*(admissions!$U$2:$U$78)) | D13: =SUMPRODUCT((TEXT(payments!$C$2:$C$501,"yyyy-mm")=$A13)*(payments!$D$2:$D$501)) | E13: =SUMPRODUCT((TEXT(expenses!$A$2:$A$501,"yyyy-mm")=$A13)*(expenses!$D$2:$D$501)) | F13: =D13-E13 | G13: =SUMPRODUCT((TEXT(admissions!$AB$2:$AB$78,"yyyy-mm")<=$A13)*(admissions!$W$2:$W$78)) | H13: =SUMPRODUCT((admissions!$W$2:$W$78>0)*(TEXT(admissions!$AB$2:$AB$78,"yyyy-mm")<=$A13)) | I13: =SUMPRODUCT((TEXT(expenses!$A$2:$A$501,"yyyy-mm")=$A13)*(expenses!$B$2:$B$501="Salary")*(expenses!$D$2:$D$501)) | J13: =SUMPRODUCT(((TEXT(expenses!$A$2:$A$501,"yyyy-mm")=$A13)*((expenses!$B$2:$B$501="Marketing")+(expenses!$B$2:$B$501="Advertisement")))*(expenses!$D$2:$D$501)) | K13: =SUMPRODUCT((TEXT(expenses!$A$2:$A$501,"yyyy-mm")=$A13)*(expenses!$B$2:$B$501="Rent")*(expenses!$D$2:$D$501)) | L13: =SUMPRODUCT((TEXT(expenses!$A$2:$A$501,"yyyy-mm")=$A13)*(expenses!$B$2:$B$501="Software")*(expenses!$D$2:$D$501)) | M13: =E13-I13-J13-K13-L13

Sheet batch-dashboard
A1: =IF(batches!A2="","",batches!A2) | G1: =IF(batches!A3="","",batches!A3)
A2: Level / Mode | B2: =IF(A1="","",batches!B2&" / "&batches!C2) | G2: Level / Mode | H2: =IF(G1="","",batches!B3&" / "&batches!C3)
A3: Dates | B3: =IF(A1="","",TEXT(batches!D2,"yyyy-mm-dd")&" to "&TEXT(batches!E2,"yyyy-mm-dd")) | G3: Dates | H3: =IF(G1="","",TEXT(batches!D3,"yyyy-mm-dd")&" to "&TEXT(batches!E3,"yyyy-mm-dd"))
A4: Duration | B4: =IF(OR(batches!D2="",batches!E2=""),"",batches!E2-batches!D2+1&" days") | G4: Duration | H4: =IF(OR(batches!D3="",batches!E3=""),"",batches!E3-batches!D3+1&" days")
A5: Timing | B5: =IF(A1="","",batches!F2) | G5: Timing | H5: =IF(G1="","",batches!F3)
A6: Capacity | B6: =IF(A1="","",batches!G2) | G6: Capacity | H6: =IF(G1="","",batches!G3)
A7: Enrolled | B7: =IF(A1="","",COUNTIF(admissions!$M:$M,batches!A2)) | G7: Enrolled | H7: =IF(G1="","",COUNTIF(admissions!$M:$M,batches!A3))
A8: Available | B8: =IF(OR(batches!A2="",batches!G2=""),"",batches!G2-COUNTIF(admissions!$M:$M,batches!A2)) | G8: Available | H8: =IF(OR(batches!A3="",batches!G3=""),"",batches!G3-COUNTIF(admissions!$M:$M,batches!A3))
A9: Student List | G9: Student List
A10: =IFERROR(__xludf.DUMMYFUNCTION("IF(batches!A2="""","""",TEXTJOIN(CHAR(10),TRUE,FILTER(admissions!$G$2:$G$78,admissions!$M$2:$M$78=batches!A2,"""")))"),"#N/A") | G10: =IFERROR(__xludf.DUMMYFUNCTION("IF(batches!A3="""","""",TEXTJOIN(CHAR(10),TRUE,FILTER(admissions!$G$2:$G$78,admissions!$M$2:$M$78=batches!A3,"""")))"),"#N/A")
A13: =IF(batches!A4="","",batches!A4) | G13: =IF(batches!A5="","",batches!A5)
A14: Level / Mode | B14: =IF(A13="","",batches!B4&" / "&batches!C4) | G14: Level / Mode | H14: =IF(G13="","",batches!B5&" / "&batches!C5)
A15: Dates | B15: =IF(A13="","",TEXT(batches!D4,"yyyy-mm-dd")&" to "&TEXT(batches!E4,"yyyy-mm-dd")) | G15: Dates | H15: =IF(G13="","",TEXT(batches!D5,"yyyy-mm-dd")&" to "&TEXT(batches!E5,"yyyy-mm-dd"))
A16: Duration | B16: =IF(OR(batches!D4="",batches!E4=""),"",batches!E4-batches!D4+1&" days") | G16: Duration | H16: =IF(OR(batches!D5="",batches!E5=""),"",batches!E5-batches!D5+1&" days")
A17: Timing | B17: =IF(A13="","",batches!F4) | G17: Timing | H17: =IF(G13="","",batches!F5)
A18: Capacity | B18: =IF(A13="","",batches!G4) | G18: Capacity | H18: =IF(G13="","",batches!G5)
A19: Enrolled | B19: =IF(A13="","",COUNTIF(admissions!$M:$M,batches!A4)) | G19: Enrolled | H19: =IF(G13="","",COUNTIF(admissions!$M:$M,batches!A5))
A20: Available | B20: =IF(OR(batches!A4="",batches!G4=""),"",batches!G4-COUNTIF(admissions!$M:$M,batches!A4)) | G20: Available | H20: =IF(OR(batches!A5="",batches!G5=""),"",batches!G5-COUNTIF(admissions!$M:$M,batches!A5))
A21: Student List | G21: Student List
A22: =IFERROR(__xludf.DUMMYFUNCTION("IF(batches!A4="""","""",TEXTJOIN(CHAR(10),TRUE,FILTER(admissions!$G$2:$G$78,admissions!$M$2:$M$78=batches!A4,"""")))"),"#N/A") | G22: =IFERROR(__xludf.DUMMYFUNCTION("IF(batches!A5="""","""",TEXTJOIN(CHAR(10),TRUE,FILTER(admissions!$G$2:$G$78,admissions!$M$2:$M$78=batches!A5,"""")))"),"#N/A")
A25: =IF(batches!A6="","",batches!A6) | G25: =IF(batches!A7="","",batches!A7)
A26: Level / Mode | B26: =IF(A25="","",batches!B6&" / "&batches!C6) | G26: Level / Mode | H26: =IF(G25="","",batches!B7&" / "&batches!C7)
A27: Dates | B27: =IF(A25="","",TEXT(batches!D6,"yyyy-mm-dd")&" to "&TEXT(batches!E6,"yyyy-mm-dd")) | G27: Dates | H27: =IF(G25="","",TEXT(batches!D7,"yyyy-mm-dd")&" to "&TEXT(batches!E7,"yyyy-mm-dd"))
A28: Duration | B28: =IF(OR(batches!D6="",batches!E6=""),"",batches!E6-batches!D6+1&" days") | G28: Duration | H28: =IF(OR(batches!D7="",batches!E7=""),"",batches!E7-batches!D7+1&" days")
A29: Timing | B29: =IF(A25="","",batches!F6) | G29: Timing | H29: =IF(G25="","",batches!F7)
A30: Capacity | B30: =IF(A25="","",batches!G6) | G30: Capacity | H30: =IF(G25="","",batches!G7)
A31: Enrolled | B31: =IF(A25="","",COUNTIF(admissions!$M:$M,batches!A6)) | G31: Enrolled | H31: =IF(G25="","",COUNTIF(admissions!$M:$M,batches!A7))
A32: Available | B32: =IF(OR(batches!A6="",batches!G6=""),"",batches!G6-COUNTIF(admissions!$M:$M,batches!A6)) | G32: Available | H32: =IF(OR(batches!A7="",batches!G7=""),"",batches!G7-COUNTIF(admissions!$M:$M,batches!A7))
A33: Student List | G33: Student List
A34: =IFERROR(__xludf.DUMMYFUNCTION("IF(batches!A6="""","""",TEXTJOIN(CHAR(10),TRUE,FILTER(admissions!$G$2:$G$78,admissions!$M$2:$M$78=batches!A6,"""")))"),"#N/A") | G34: =IFERROR(__xludf.DUMMYFUNCTION("IF(batches!A7="""","""",TEXTJOIN(CHAR(10),TRUE,FILTER(admissions!$G$2:$G$78,admissions!$M$2:$M$78=batches!A7,"""")))"),"#N/A")
A37: =IF(batches!A8="","",batches!A8) | G37: =IF(batches!A9="","",batches!A9)
A38: Level / Mode | B38: =IF(A37="","",batches!B8&" / "&batches!C8) | G38: Level / Mode | H38: =IF(G37="","",batches!B9&" / "&batches!C9)
A39: Dates | B39: =IF(A37="","",TEXT(batches!D8,"yyyy-mm-dd")&" to "&TEXT(batches!E8,"yyyy-mm-dd")) | G39: Dates | H39: =IF(G37="","",TEXT(batches!D9,"yyyy-mm-dd")&" to "&TEXT(batches!E9,"yyyy-mm-dd"))
A40: Duration | B40: =IF(OR(batches!D8="",batches!E8=""),"",batches!E8-batches!D8+1&" days") | G40: Duration | H40: =IF(OR(batches!D9="",batches!E9=""),"",batches!E9-batches!D9+1&" days")
A41: Timing | B41: =IF(A37="","",batches!F8) | G41: Timing | H41: =IF(G37="","",batches!F9)
A42: Capacity | B42: =IF(A37="","",batches!G8) | G42: Capacity | H42: =IF(G37="","",batches!G9)
A43: Enrolled | B43: =IF(A37="","",COUNTIF(admissions!$M:$M,batches!A8)) | G43: Enrolled | H43: =IF(G37="","",COUNTIF(admissions!$M:$M,batches!A9))
A44: Available | B44: =IF(OR(batches!A8="",batches!G8=""),"",batches!G8-COUNTIF(admissions!$M:$M,batches!A8)) | G44: Available | H44: =IF(OR(batches!A9="",batches!G9=""),"",batches!G9-COUNTIF(admissions!$M:$M,batches!A9))
A45: Student List | G45: Student List
A46: =IFERROR(__xludf.DUMMYFUNCTION("IF(batches!A8="""","""",TEXTJOIN(CHAR(10),TRUE,FILTER(admissions!$G$2:$G$78,admissions!$M$2:$M$78=batches!A8,"""")))"),"#N/A") | G46: =IFERROR(__xludf.DUMMYFUNCTION("IF(batches!A9="""","""",TEXTJOIN(CHAR(10),TRUE,FILTER(admissions!$G$2:$G$78,admissions!$M$2:$M$78=batches!A9,"""")))"),"#N/A")
...

Sheet admission_queue
A1: Timestamp | B1: Payload | C1: Status
